Workbook

Sheet Defeitos_Tuneis
A1: ID_Registro | B1: ID_Defeito | C1: ID_Ronda | D1: Atualização | E1: Tipo de Inspeção | F1: Data | G1: Responsável | H1: Status Defeito | I1: SUB_Defeitos_Tu | J1: km_Nominal | K1: Equip_Super | L1: Equip_Tunel | M1: km Início Defeito | N1: km Fim Defeito | O1: Extensão Defeito (m) | P1: Latitude Inicio | Q1: Latitude Fim | R1: Longitude Inicio | S1: Longitude Fim | T1: Lado | U1: DEFEITO | V1: Prioridade | W1: Observação | X1: Fotos | Y1: OS | Z1: Sub_Trecho | AA1: __PowerAppsId__
A2: 98 | B2: 532 | D2: 0 | E2: Cadastral | F2: 44488 | G2: Azimute | H2: Novo | I2: 17 | J2: 313.834 | K2: 17/313780-313920cv | L2: 17/313724-313944tu | O2: 0 | U2: Tunel - Queda De Blocos | V2: P2 | X2: https://data-scope.s3.amazonaws.com/images/2021/10/23683/374fc9366629a88218cbd12e2c9c0b5a.jpg | Z2: LLS-NRI | AA2: 72b18e2d-1b87-4041-9b9f-e09206aeec00
A3: 99 | B3: 533 | D3: 0 | E3: Cadastral | F3: 44488 | G3: Azimute | H3: Novo | I3: 17 | J3: 313.834 | K3: 17/313780-313920cv | L3: 17/313724-313944tu | O3: 0 | U3: Tunel - Infiltração | V3: P3 | X3: https://data-scope.s3.amazonaws.com/images/2021/10/23683/4e49211310ab6ca8f6247686d9df4cae.jpg | Z3: LLS-NRI | AA3: 8a32898d-f753-4ba4-9495-7678d0c44ab1
A4: 100 | B4: 535 | D4: 0 | E4: Cadastral | F4: 44488 | G4: Azimute | H4: Novo | I4: 17 | J4: 318.563 | K4: 17/318280-318820tg | L4: 17/318158-318967tu | O4: 0 | U4: Tunel - Infiltração | V4: P3 | X4: https://data-scope.s3.amazonaws.com/images/2021/10/23683/fc58010b52b1c4da7938aa3438c5ebc9.jpg | Z4: LLS-NRI | AA4: 1a7e2c1a-529e-4955-ab1d-a54e9b5a63b4
A5: 101 | B5: 536 | D5: 0 | E5: Cadastral | F5: 44488 | G5: Azimute | H5: Novo | I5: 17 | J5: 318.563 | K5: 17/318280-318820tg | L5: 17/318158-318967tu | O5: 0 | U5: Tunel - Infiltração | V5: P3 | X5: https://data-scope.s3.amazonaws.com/images/2021/10/23683/fdf8fbb547d3c895541d525ffb81bb43.jpg | Z5: LLS-NRI | AA5: a5f54219-7f01-4063-812f-cdf6e7c91c7c
A6: 102 | B6: 537 | D6: 0 | E6: Cadastral | F6: 44488 | G6: Azimute | H6: Novo | I6: 17 | J6: 319.375 | K6: 17/319190-319700tg | L6: 17/319159-319591tu | O6: 0 | U6: Tunel - Revestimento Danificado | V6: P2 | X6: https://data-scope.s3.amazonaws.com/images/2021/10/23683/503619222851ad27f7e8dca5c737a695.jpg | Z6: LLS-NRI | AA6: 07eb9db4-e1fe-425e-ab90-0e800e576a3d
A7: 103 | B7: 538 | D7: 0 | E7: Cadastral | F7: 44488 | G7: Azimute | H7: Novo | I7: 17 | J7: 319.375 | K7: 17/319190-319700tg | L7: 17/319159-319591tu | O7: 0 | U7: Tunel - Infiltração | V7: P2 | X7: https://data-scope.s3.amazonaws.com/images/2021/10/23683/45e12cfce02b5eaa5bffc857e8a99bb1.jpg | Z7: LLS-NRI | AA7: 70a4ee3a-83e6-4038-896c-46478104fbf3
A8: 104 | B8: 539 | D8: 0 | E8: Cadastral | F8: 44488 | G8: Azimute | H8: Novo | I8: 17 | J8: 319.375 | K8: 17/319190-319700tg | L8: 17/319159-319591tu | O8: 0 | U8: Tunel - Infiltração | V8: P2 | X8: https://data-scope.s3.amazonaws.com/images/2021/10/23683/35bdaaff4e73d4264d827fdfb08727e6.jpg | Z8: LLS-NRI | AA8: 7c6d0d14-0e9b-4641-b58e-5408eb01455a
A9: 105 | B9: 540 | D9: 0 | E9: Cadastral | F9: 44488 | G9: Azimute | H9: Novo | I9: 17 | J9: 319.375 | K9: 17/319190-319700tg | L9: 17/319159-319591tu | O9: 0 | U9: Tunel - Infiltração | V9: P3 | X9: https://data-scope.s3.amazonaws.com/images/2021/10/23683/00d241ffe4253a798e96eba72c55199a.jpg | Z9: LLS-NRI | AA9: 590bd899-bbf8-4626-a517-018b48788b20
A10: 106 | B10: 541 | D10: 0 | E10: Cadastral | F10: 44488 | G10: Azimute | H10: Novo | I10: 17 | J10: 319.375 | K10: 17/319190-319700tg | L10: 17/319159-319591tu | O10: 0 | U10: Tunel - Infiltração | V10: P2 | X10: https://data-scope.s3.amazonaws.com/images/2021/10/23683/a4b13a627968d293ec8b774258c8c46a.jpg | Z10: LLS-NRI | AA10: def35b22-05bc-4d19-99c7-4e56f5eb1e11
A11: 107 | B11: 542 | D11: 0 | E11: Cadastral | F11: 44488 | G11: Azimute | H11: Novo | I11: 17 | J11: 319.375 | K11: 17/319190-319700tg | L11: 17/319159-319591tu | O11: 0 | U11: Tunel - Infiltração | V11: P3 | X11: https://data-scope.s3.amazonaws.com/images/2021/10/23683/aad931a81177a49521f7d51cdc5f9741.jpg | Z11: LLS-NRI | AA11: 778ca65c-2e4d-4686-b334-80cf3d9baed7
A12: 108 | B12: 543 | D12: 0 | E12: Cadastral | F12: 44488 | G12: Azimute | H12: Novo | I12: 17 | J12: 319.375 | K12: 17/319190-319700tg | L12: 17/319159-319591tu | O12: 0 | U12: Tunel - Infiltração | V12: P1 | X12: https://data-scope.s3.amazonaws.com/images/2021/10/23683/76ebdf550ef7f06104e50ab302a71eaa.jpg | Z12: LLS-NRI | AA12: 658ff300-0bad-4327-9fb6-02112d989506
A13: 198 | B13: 505 | D13: 0 | E13: Cadastral | F13: 44489 | G13: Azimute | H13: Novo | I13: 17 | J13: 307.629 | K13: 17/307610-308130cv | L13: 17/307500-307757tu | O13: 0 | U13: Tunel - Queda De Blocos | V13: P2 | X13: https://data-scope.s3.amazonaws.com/images/2021/10/23683/6460ef20ed5f0bc55df6d810caf1d4d6.jpg | Z13: LLS-NRI | AA13: c5b648a1-796b-45f7-a224-b277de348f97
... A18: 203 | B18: 510 | D18: 0 | E18: Cadastral | F18: 44489 | G18: Azimute | H18: Novo | I18: 17 | J18: 307.629 | K18: 17/307610-308130cv | L18: 17/307500-307757tu | O18: 0 | U18: Tunel - Queda De Blocos | V18: P2 | X18: https://data-scope.s3.amazonaws.com/images/2021/10/23683/12f6231ab60e5717a944cea147fcf9e7.jpg | Z18: LLS-NRI | AA18: d85777d9-01ec-4792-82b4-a0cd8ebfb158
A19: 204 | B19: 511 | D19: 0 | E19: Cadastral | F19: 44489 | G19: Azimute | H19: Novo | I19: 17 | J19: 307.629 | K19: 17/307610-308130cv | L19: 17/307500-307757tu | O19: 0 | U19: Tunel - Drenagem Assoreada | V19: P3 | W19: https://data-scope.s3.amazonaws.com/images/2021/10/23683/8e272761296b73b524c899d775023e0a.jpg | Z19: LLS-NRI | AA19: f6a4aaf6-cf14-46c1-8807-84df84e65495
A20: 205 | B20: 512 | D20: 0 | E20: Cadastral | F20: 44489 | G20: Azimute | H20: Novo | I20: 17 | J20: 307.629 | K20: 17/307610-308130cv | L20: 17/307500-307757tu | O20: 0 | U20: Tunel - Infiltração | V20: P3 | X20: https://data-scope.s3.amazonaws.com/images/2021/10/23683/9a6d9cb15e132621daeb76c3b196a4ef.jpg | Z20: LLS-NRI | AA20: 0a262e79-85a0-4059-b0e6-7757d7ecb8b6
A21: 206 | B21: 515 | D21: 0 | E21: Cadastral | F21: 44489 | G21: Azimute | H21: Novo | I21: 17 | J21: 309.23 | K21: 17/309130-309460cv | L21: 17/309131-309328tu | O21: 0 | U21: Tunel - Drenagem Assoreada | V21: P3 | W21: https://data-scope.s3.amazonaws.com/images/2021/10/23683/af92cd8ab8dd22432dcf7362d7eedb4f.jpg | Z21: LLS-NRI | AA21: c1990061-072a-41a8-8b65-a4432ba84538
A22: 207 | B22: 516 | D22: 0 | E22: Cadastral | F22: 44489 | G22: Azimute | H22: Novo | I22: 17 | J22: 309.23 | K22: 17/309130-309460cv | L22: 17/309131-309328tu | O22: 0 | U22: Tunel - Infiltração | V22: P1 | X22: https://data-scope.s3.amazonaws.com/images/2021/10/23683/13585778f506df22704b39ebb2d2afbb.jpg | Z22: LLS-NRI | AA22: 1323b5c4-32e8-495f-8cdf-38b414d74ad1
A23: 208 | B23: 517 | D23: 0 | E23: Cadastral | F23: 44489 | G23: Azimute | H23: Novo | I23: 17 | J23: 309.23 | K23: 17/309130-309460cv | L23: 17/309131-309328tu | O23: 0 | U23: Tunel - Infiltração | V23: P3 | X23: https://data-scope.s3.amazonaws.com/images/2021/10/23683/a3889882e95d130a2943eb3d489144de.jpg | Z23: LLS-NRI | AA23: af1bace1-b107-4f88-b11b-89d4d0de2dc1
A24: 209 | B24: 518 | D24: 0 | E24: Cadastral | F24: 44489 | G24: Azimute | H24: Novo | I24: 17 | J24: 309.23 | K24: 17/309130-309460cv | L24: 17/309131-309328tu | O24: 0 | U24: Tunel - Queda De Blocos | V24: P2 | X24: https://data-scope.s3.amazonaws.com/images/2021/10/23683/6051a34ad9c5a6a4fbaa3776b6158a62.jpg | Z24: LLS-NRI | AA24: c9f041bd-4712-4229-891d-d02efba24f8e
A25: 210 | B25: 519 | D25: 0 | E25: Cadastral | F25: 44489 | G25: Azimute | H25: Novo | I25: 17 | J25: 309.23 | K25: 17/309130-309460cv | L25: 17/309131-309328tu | O25: 0 | U25: Tunel - Drenagem Colmatada/Insuficiente | V25: P2 | X25: https://data-scope.s3.amazonaws.com/images/2021/10/23683/ebec496b9f508516665082bcc661aa3d.jpg | Z25: LLS-NRI | AA25: 7eb087a9-cf77-4797-becb-480d68a018ec
A26: 211 | B26: 520 | D26: 0 | E26: Cadastral | F26: 44489 | G26: Azimute | H26: Novo | I26: 17 | J26: 310.733 | K26: 17/310650-310870tg | L26: 17/310555-310910tu | O26: 0 | U26: Tunel - Infiltração | V26: P3 | X26: https://data-scope.s3.amazonaws.com/images/2021/10/23683/d4cc1f84166f0726ec3a9d01702c1877.jpg | Z26: LLS-NRI | AA26: 2ce99f5e-8981-4ad0-8d07-c10078f54d7a
A27: 212 | B27: 521 | D27: 0 | E27: Cadastral | F27: 44489 | G27: Azimute | H27: Novo | I27: 17 | J27: 310.733 | K27: 17/310650-310870tg | L27: 17/310555-310910tu | O27: 0 | U27: Tunel - Queda De Blocos | V27: P3 | X27: https://data-scope.s3.amazonaws.com/images/2021/10/23683/e06e71c5b715f8bd9e0df3612b15e36a.jpg | Z27: LLS-NRI | AA27: 89330cf0-6c2e-47a0-9bd6-dc3803088028
A28: 213 | B28: 522 | D28: 0 | E28: Cadastral | F28: 44489 | G28: Azimute | H28: Novo | I28: 17 | J28: 310.733 | K28: 17/310650-310870tg | L28: 17/310555-310910tu | O28: 0 | U28: Tunel - Queda De Blocos | V28: P3 | X28: https://data-scope.s3.amazonaws.com/images/2021/10/23683/c0586dc1fa8e34c1850e9de9a9a3b032.jpg | Z28: LLS-NRI | AA28: b5619ae9-6bf8-4ff2-87fe-77dcf4d34967
A29: 214 | B29: 523 | D29: 0 | E29: Cadastral | F29: 44489 | G29: Azimute | H29: Novo | I29: 17 | J29: 310.733 | K29: 17/310650-310870tg | L29: 17/310555-310910tu | O29: 0 | U29: Tunel - Queda De Blocos | V29: P3 | X29: https://data-scope.s3.amazonaws.com/images/2021/10/23683/50e61a68bb9dc4c575b631735cc99cdc.jpg | Z29: LLS-NRI | AA29: 1bbfaff8-fa3c-4eec-a10c-48827fb3f786
A30: 321999 | B30: 210 | D30: 0 | E30: Rotineira | F30: 45400 | G30: Arielcio Silva | H30: Reclassificado | I30: 16 | J30: 191.64 | K30: 16/191108-191975tg | L30: 16/191199-191921tu | P30: -27.042272 | R30: -50.351512 | T30: Emboque Inicial | U30: Tunel - Emboque Danificado | V30: P2 | W30: Armadura esposta' entrada túnel na aboboda. | X30: 6551-6693 | Z30: LIA-LFJ | AA30: 5f8f1fcc-f240-41e4-89af-090fed5617cb
A31: 260 | B31: 211 | D31: 0 | E31: Ronda | F31: 44490 | G31: Nicholas | H31: Novo | I31: 16 | J31: 228.42 | K31: 16/228597-229760tg | L31: 16/237641-238429tu | P31: -27.308992 | R31: -50.312968 | T31: Emboque Inicial | U31: Tunel - Queda De Blocos | V31: P2 | W31: Tubel com queda de blocos infiltrações grande e drenagem trancada | Z31: LFS-LLS | AA31: 0d95b18c-6b4d-4745-a194-c78429ee257f
A32: 261 | B32: 212 | D32: 0 | E32: Ronda | F32: 44490 | G32: Nicholas | H32: Novo | I32: 16 | J32: 237.645 | K32: 16/237325-237809cv | L32: 16/237641-238429tu | P32: -27.37224 | R32: -50.288632 | U32: Tunel - Emboque Danificado | V32: P1 | W32: Queda de barreira emboque norte, problema de drenagem e barreira constante queda | Z32: LFS-LLS | AA32: 34c35065-55bd-416a-ab74-1ea472a90f7f
A33: 262 | B33: 513 | D33: 0 | E33: Cadastral | F33: 44490 | G33: Azimute | H33: Novo | I33: 17 | J33: 308.248 | K33: 17/308130-309130tg | L33: 17/308100-308396tu | O33: 0 | U33: Tunel - Infiltração | V33: P3 | X33: https://data-scope.s3.amazonaws.com/images/2021/10/23683/f8d8d01d5c25f79d469760631f945df7.jpg | Z33: LLS-NRI | AA33: 1657513e-6fd9-4856-9682-28fc37f13190
A34: 263 | B34: 514 | D34: 0 | E34: Cadastral | F34: 44490 | G34: Azimute | H34: Novo | I34: 17 | J34: 308.248 | K34: 17/308130-309130tg | L34: 17/308100-308396tu | O34: 0 | U34: Tunel - Infiltração | V34: P2 | X34: https://data-scope.s3.amazonaws.com/images/2021/10/23683/ba1f5866e439f1d400b465123471133d.jpg | Z34: LLS-NRI | AA34: 50047d84-b33f-46c7-98ae-6f81975771a4
A35: 264 | B35: 534 | D35: 0 | E35: Cadastral | F35: 44490 | G35: Azimute | H35: Novo | I35: 17 | J35: 315.183 | K35: 17/314350-315460cv | L35: 17/314561-315804tu | O35: 0 | U35: Tunel - Infiltração | V35: P3 | X35: https://data-scope.s3.amazonaws.com/images/2021/10/23683/5e46e53705556947a8e568c6074504f2.jpg | Z35: LLS-NRI | AA35: f56771a0-210d-48c7-970f-e7867a66b102
A36: 265 | B36: 602 | D36: 0 | E36: Cadastral | F36: 44490 | G36: Azimute | H36: Novo | I36: 17 | J36: 349.766 | K36: 17/349693-349878cv | L36: 17/349528-350003tu | O36: 0 | U36: Tunel - Infiltração | V36: P3 | Z36: LLS-NRI | AA36: 37682830-3c45-4601-bb48-7c339189fe87
A37: 336 | B37: 594 | D37: 0 | E37: Cadastral | F37: 44498 | G37: Azimute | H37: Novo | I37: 17 | J37: 348.363 | K37: 17/347684-348689tg | L37: 17/348186-348540tu | O37: 0 | U37: Tunel - Infiltração | V37: P3 | Z37: LLS-NRI | AA37: bc96882f-ee14-49e0-b707-35626ee80137
A38: 337 | B38: 595 | D38: 0 | E38: Cadastral | F38: 44498 | G38: Azimute | H38: Novo | I38: 17 | J38: 348.363 | K38: 17/347684-348689tg | L38: 17/348186-348540tu | O38: 0 | U38: Tunel - Drenagem Danificada | V38: P3 | Z38: LLS-NRI | AA38: 6ae5e71c-d19f-43dc-8fb2-8db8bba67057
A39: 338 | B39: 596 | D39: 0 | E39: Cadastral | F39: 44498 | G39: Azimute | H39: Novo | I39: 17 | J39: 348.363 | K39: 17/347684-348689tg | L39: 17/348186-348540tu | O39: 0 | U39: Tunel - Queda De Blocos | V39: P3 | Z39: LLS-NRI | AA39: 6d627e53-9501-4b5f-9cb4-59d3ecb60589
A40: 339 | B40: 597 | D40: 0 | E40: Cadastral | F40: 44498 | G40: Azimute | H40: Novo | I40: 17 | J40: 348.363 | K40: 17/347684-348689tg | L40: 17/348186-348540tu | O40: 0 | U40: Tunel - Queda De Blocos | V40: P3 | Z40: LLS-NRI | AA40: 48079b27-0e47-4fbc-9439-5f49be3edc1b
A41: 340 | B41: 598 | D41: 0 | E41: Cadastral | F41: 44498 | G41: Azimute | H41: Novo | I41: 17 | J41: 348.363 | K41: 17/347684-348689tg | L41: 17/348186-348540tu | O41: 0 | U41: Tunel - Queda De Blocos | V41: P2 | Z41: LLS-NRI | AA41: b67f909b-18a4-4bc3-a2ae-896a534ca7e7
A42: 341 | B42: 599 | D42: 0 | E42: Cadastral | F42: 44498 | G42: Azimute | H42: Novo | I42: 17 | J42: 348.363 | K42: 17/347684-348689tg | L42: 17/348186-348540tu | O42: 0 | U42: Tunel - Queda De Blocos | V42: P3 | Z42: LLS-NRI | AA42: ec5b4a97-cf55-470f-b0f4-fc790e9f134d
A43: 342 | B43: 600 | D43: 0 | E43: Cadastral | F43: 44498 | G43: Azimute | H43: Novo | I43: 17 | J43: 348.363 | K43: 17/347684-348689tg | L43: 17/348186-348540tu | O43: 0 | U43: Tunel - Queda De Blocos | V43: P3 | Z43: LLS-NRI | AA43: c5977949-e68a-49f2-9ecc-b3e0ab3fc4ad
A44: 343 | B44: 601 | D44: 0 | E44: Cadastral | F44: 44498 | G44: Azimute | H44: Novo | I44: 17 | J44: 348.363 | K44: 17/347684-348689tg | L44: 17/348186-348540tu | O44: 0 | U44: Tunel - Queda De Blocos | V44: P3 | Z44: LLS-NRI | AA44: 505fbd6a-61aa-4837-bba9-b32b4517263f
...

Sheet Faltantes
A1: Eqto | B1: Check
A2: 1/331901-333557tu | B2: =COUNTIF(Equipamento_Tunel!$H$2:$H$158,A2) -> 0
A3: 1/334627-335242tu | B3: =COUNTIF(Equipamento_Tunel!$H$2:$H$158,A3) -> 0
A4: 7/415929-416214tu | B4: =COUNTIF(Equipamento_Tunel!$H$2:$H$158,A4) -> 0
A5: 7/425046-425159tu | B5: =COUNTIF(Equipamento_Tunel!$H$2:$H$158,A5) -> 0
A6: 7/425579-425711tu | B6: =COUNTIF(Equipamento_Tunel!$H$2:$H$158,A6) -> 0
A7: 7/426215-426503tu | B7: =COUNTIF(Equipamento_Tunel!$H$2:$H$158,A7) -> 0
A8: 7/427274-427876tu | B8: =COUNTIF(Equipamento_Tunel!$H$2:$H$158,A8) -> 0
A9: 7/439316-439518tu | B9: =COUNTIF(Equipamento_Tunel!$H$2:$H$158,A9) -> 0
A10: 7/479906-480173tu | B10: =COUNTIF(Equipamento_Tunel!$H$2:$H$158,A10) -> 0
A11: 7/480441-480726tu | B11: =COUNTIF(Equipamento_Tunel!$H$2:$H$158,A11) -> 0
A12: 7/484321-484771tu | B12: =COUNTIF(Equipamento_Tunel!$H$2:$H$158,A12) -> 0
A13: 7/495439-495775tu | B13: =COUNTIF(Equipamento_Tunel!$H$2:$H$158,A13) -> 0
... A190: 92/103043-103271tu | B190: =COUNTIF(Equipamento_Tunel!$H$2:$H$158,A190) -> 0
B191: =COUNTIF(Equipamento_Tunel!$H$2:$H$158,A191) -> 0
B192: =COUNTIF(Equipamento_Tunel!$H$2:$H$158,A192) -> 0
B193: =COUNTIF(Equipamento_Tunel!$H$2:$H$158,A193) -> 0
B194: =COUNTIF(Equipamento_Tunel!$H$2:$H$158,A194) -> 0
B195: =COUNTIF(Equipamento_Tunel!$H$2:$H$158,A195) -> 0
B196: =COUNTIF(Equipamento_Tunel!$H$2:$H$158,A196) -> 0
B197: =COUNTIF(Equipamento_Tunel!$H$2:$H$158,A197) -> 0
B198: =COUNTIF(Equipamento_Tunel!$H$2:$H$158,A198) -> 0
B199: =COUNTIF(Equipamento_Tunel!$H$2:$H$158,A199) -> 0
B200: =COUNTIF(Equipamento_Tunel!$H$2:$H$158,A200) -> 0
B201: =COUNTIF(Equipamento_Tunel!$H$2:$H$158,A201) -> 0
B202: =COUNTIF(Equipamento_Tunel!$H$2:$H$158,A202) -> 0
... B3198: =COUNTIF(Equipamento_Tunel!$H$2:$H$158,A3198) -> 0
A3199: LAT/015800-015900tu | B3199: =COUNTIF(Equipamento_Tunel!$H$2:$H$158,A3199) -> 0
A3200: 15/101000-101100tu | B3200: =COUNTIF(Equipamento_Tunel!$H$2:$H$158,A3200) -> 0
A3201: 18/070700-070900tu | B3201: =COUNTIF(Equipamento_Tunel!$H$2:$H$158,A3201) -> 0

Sheet Cadastro_Tunel
A1: SUB | B1: SUB_2 | C1: Km NOMINAL | D1: kmi | E1: kmf | F1: EXTENSÃO | G1: Equip_Tunel | H1: Equip_Super | I1: NOME | J1: Pre_Inspecao | K1: Sub_Trecho | L1: __PowerAppsId__ | M1: ID_Cad_Tuneis
A2: 1 | B2: 1 | C2: 332.7285 | D2: 331.901 | E2: 333.557 | F2: 1657 | G2: 1/331901-333557tu | H2: 1/332630-332730tg | J2: 0 | K2: LAP-LMG | L2: b5a7dc30-f0ab-4fa8-bd2f-a5f42897502c | M2: 1
A3: 1 | B3: 1 | C3: 334.9345 | D3: 334.627 | E3: 335.242 | F3: 615 | G3: 1/334627-335242tu | H3: 1/334810-335080tg | J3: 0 | K3: LAP-LMG | L3: 14eb131a-3231-4f3c-b0a6-789399ae41b9 | M3: 2
A4: 7 | B4: 7 | C4: 416.0715 | D4: 415.929 | E4: 416.214 | F4: 285 | G4: 7/415929-416214tu | H4: 7/415650-416160cv | J4: 0 | K4: LIH-LFI | L4: 04e106a8-a65a-494c-8896-60372773ac22 | M4: 3
A5: 7 | B5: 7 | C5: 425.1025 | D5: 425.046 | E5: 425.159 | F5: 113 | G5: 7/425046-425159tu | H5: 7/425087-425224tg | J5: 0 | K5: LFI-LOD | L5: 138468c1-a45a-4db9-8658-a5dc6d8c48a9 | M5: 4
A6: 7 | B6: 7 | C6: 425.6445 | D6: 425.579 | E6: 425.711 | F6: 131 | G6: 7/425579-425711tu | H6: 7/425224-425724cv | J6: 0 | K6: LFI-LOD | L6: e183904f-7767-4c8c-b6db-9e702a0ad7d1 | M6: 5
A7: 7 | B7: 7 | C7: 426.359 | D7: 426.215 | E7: 426.503 | F7: 288 | G7: 7/426215-426503tu | H7: 7/426293-426386tg | J7: 0 | K7: LFI-LOD | L7: eed53502-7ad8-4dba-9593-ea315d925d91 | M7: 6
A8: 7 | B8: 7 | C8: 427.575 | D8: 427.274 | E8: 427.876 | F8: 602 | G8: 7/427274-427876tu | H8: 7/427546-427858tg | J8: 0 | K8: LFI-LOD | L8: 43ed96c5-10c7-4b08-9a58-fe293e7e6896 | M8: 7
A9: 7 | B9: 7 | C9: 439.417 | D9: 439.316 | E9: 439.518 | F9: 202 | G9: 7/439316-439518tu | H9: 7/439250-439620cv | J9: 0 | K9: LFI-LOD | L9: d542414d-e79f-491b-b94e-8eef217ec178 | M9: 8
A10: 7 | B10: 7 | C10: 480.0395 | D10: 479.906 | E10: 480.173 | F10: 267 | G10: 7/479906-480173tu | H10: 7/480015-480315cv | J10: 0 | K10: LFI-LOD | L10: 7fc83f75-3a1a-4282-a883-1ec9cd3e7b1f | M10: 9
A11: 7 | B11: 7 | C11: 480.583 | D11: 480.441 | E11: 480.726 | F11: 286 | G11: 7/480441-480726tu | H11: 7/480315-480671tg | J11: 0 | K11: LFI-LOD | L11: 0c660aa1-f8d3-4b1d-b501-7e516b2db7c1 | M11: 10
A12: 7 | B12: 7 | C12: 484.546 | D12: 484.321 | E12: 484.771 | F12: 450 | G12: 7/484321-484771tu | H12: 7/483740-484860cv | J12: 0 | K12: LFI-LOD | L12: 6c5206d8-f2bd-4966-ad3b-f8f623972d32 | M12: 11
A13: 7 | B13: 7 | C13: 495.607 | D13: 495.439 | E13: 495.775 | F13: 336 | G13: 7/495439-495775tu | H13: 7/495472-495732cv | J13: 0 | K13: LFI-LOD | L13: 1e7ace72-10d1-4886-9355-ccc52ac6aa1c | M13: 12
... A113: 17 | B113: 17 | C113: 375.797 | D113: 375.622 | E113: 375.972 | F113: 350 | G113: 17/375622-375972tu | H113: 17/375669-375922cv | J113: 0 | K113: LLS-NRI | L113: 4c85a447-a54b-484a-be76-def9d073a21d | M113: 112
A114: 19 | B114: 19 | C114: 11.737 | D114: 11.18 | E114: 12.293 | F114: 1.113 | G114: 19/011180-012293tu | J114: 0 | K114: NRO-NPF | M114: 158
A115: 19 | B115: 19 | C115: 17.903 | D115: 17.82 | E115: 17.985 | F115: 0.165 | G115: 19/017820-017985tu | J115: 0 | K115: NRO-NPF | M115: 159
A116: 19 | B116: 19 | C116: 21.157 | D116: 20.938 | E116: 21.376 | F116: 0.438 | G116: 19/020938-021376tu | J116: 0 | K116: NRO-NPF | M116: 160
A117: 19 | B117: 19 | C117: 23.642 | D117: 23.421 | E117: 23.862 | F117: 0.441 | G117: 19/023421-023862tu | J117: 0 | K117: NRO-NPF | M117: 161
A118: 19 | B118: 19 | C118: 25.25 | D118: 25.128 | E118: 25.372 | F118: 0.244 | G118: 19/025128-025372tu | J118: 0 | K118: NRO-NPF | M118: 162
A119: 19 | B119: 19 | C119: 26.306 | D119: 26.118 | E119: 26.494 | F119: 0.376 | G119: 19/026118-026494tu | J119: 0 | K119: NRO-NPF | M119: 163
A120: 19 | B120: 19 | C120: 28.03 | D120: 27.907 | E120: 28.153 | F120: 0.246 | G120: 19/027907-028153tu | J120: 0 | K120: NRO-NPF | M120: 164
A121: 19 | B121: 19 | C121: 30.237 | D121: 29.865 | E121: 30.608 | F121: 0.743 | G121: 19/029865-030608tu | J121: 0 | K121: NRO-NPF | M121: 165
A122: 19 | B122: 19 | C122: 31.348 | D122: 30.874 | E122: 31.822 | F122: 0.948 | G122: 19/030874-031822tu | J122: 0 | K122: NRO-NPF | M122: 166
A123: 19 | B123: 19 | C123: 32.018 | D123: 31.92 | E123: 32.116 | F123: 0.196 | G123: 19/031920-032116tu | J123: 0 | K123: NRO-NPF | M123: 167
A124: 19 | B124: 19 | C124: 32.819 | D124: 32.213 | E124: 33.425 | F124: 1.212 | G124: 19/032213-033425tu | J124: 0 | K124: NRO-NPF | M124: 168
A125: 19 | B125: 19 | C125: 34.819 | D125: 34.306 | E125: 35.332 | F125: 1.026 | G125: 19/034306-035332tu | J125: 0 | K125: NRO-NPF | M125: 169
... A145: 19 | B145: 19 | C145: 95.184 | D145: 95.041 | E145: 95.327 | F145: 0.286 | G145: 19/095041-095327tu | J145: 0 | K145: NRO-NPF | M145: 188
A146: 21 | B146: 21 | C146: 55.676 | D146: 55.399 | E146: 55.953 | F146: 544 | G146: 21/055399-055953tu | H146: 21/055471-055940tg | J146: 0 | K146: NRO-NGL | L146: 182fedf6-6fde-499f-b3ef-1e2780ee05fc | M146: 113
A147: 21 | B147: 21 | C147: 83.63 | D147: 83.515 | E147: 83.745 | F147: 288 | G147: 21/083515-083745tu | H147: 21/083220-084200tg | J147: 0 | K147: NRO-NGL | L147: 516afa16-5897-4154-bb70-f524870946ed | M147: 114
A148: 21 | B148: 21 | C148: 97.491 | D148: 97.301 | E148: 97.682 | F148: 422 | G148: 21/097300-097682tu | H148: 21/097180-097630tg | J148: 0 | K148: NRO-NGL | L148: c65d4e4f-13aa-440c-927a-4381e6927e9c | M148: 115
A149: 24 | B149: 24 | C149: 164.959 | D149: 164.678 | E149: 165.241 | F149: 562 | G149: 24/164678-165241tu | H149: 24/164000-165000cv | J149: 0 | K149: NRP-NSM | L149: f360799b-43d5-4cbe-ae00-5a479dd0f0ed | M149: 116
A150: 25 | B150: 25 | C150: 332.593 | D150: 332.353 | E150: 332.833 | F150: 0.48 | G150: 25/332353-332833tu | J150: 0 | K150: NSM-NCY | M150: 154
A151: 37 | B151: 37 | C151: 325.969 | D151: 325.841 | E151: 326.096 | F151: 255 | G151: 37/325841-326096tu | H151: 37/325772-326582cv | J151: 0 | K151: NGB-NRH | L151: e6116b9c-b7b6-47d5-9ff4-913c69829960 | M151: 117
A152: 39 | B152: 39 | C152: 353.549 | D152: 353.282 | E152: 353.816 | F152: 0.534 | G152: 39/353282-353816tu | J152: 0 | K152: ZIE-LLZ | M152: 155
A153: 39 | B153: 39 | C153: 355.742 | D153: 355.548 | E153: 355.936 | F153: 0.388 | G153: 39/355548-355936tu | J153: 0 | K153: ZIE-LLZ | M153: 156
A154: 39 | B154: 39 | C154: 361.863 | D154: 361.589 | E154: 362.137 | F154: 0.548 | G154: 39/361589-362137tu | J154: 0 | K154: ZIE-LLZ | M154: 157
A155: 56 | B155: 56/49 | C155: 175.8005 | D155: 175.745 | E155: 175.856 | F155: 111 | G155: 49/175745-175856tu | H155: 49/175780-175840tg | I155: TÚNEL 32 B | J155: 0 | K155: ZKE-ZYU | L155: 831d9266-3dc3-4503-a809-9ab05275bb7a | M155: 118
A156: 55 | B156: 55/48 | C156: 114.152 | D156: 114.033 | E156: 114.271 | F156: 238 | G156: 55/114033-114271tu | H156: 55/113950-114276tg | I156: TÚNEL 31 | J156: 0 | K156: ZWI-ZKE | L156: a7fb4f45-39eb-4040-97a5-817a06a5ab3a | M156: 119
A157: 55 | B157: 55/48 | C157: 114.8695 | D157: 114.804 | E157: 114.935 | F157: 131 | G157: 55/114804-114935tu | H157: 55/114678-114880cv | I157: TÚNEL 30 | J157: 0 | K157: ZWI-ZKE | L157: 1ef6ad6c-a833-4660-b969-74d1d40a93f3 | M157: 120
A158: 55 | B158: 55/48 | C158: 115.505 | D158: 115.417 | E158: 115.593 | F158: 176 | G158: 55/115417-115593tu | H158: 55/115430-115650cv | I158: TÚNEL 29 | J158: 0 | K158: ZWI-ZKE | L158: 9e5ed578-1c37-4f1d-b8e1-ba5814d61bcd | M158: 121
...

Sheet Equipamento_Tunel
A1: SUB | B1: Km NOMINAL | C1: kmi | D1: kmf | E1: EXTENSÃO | F1: Equip_Tunel | G1: Equip_Super | H1: NOME | I1: Id_Cadastro_Tunel | J1: Sub_Trecho | K1: SUB_2
A2: 1 | B2: 332.729 | C2: 331.901 | D2: 333.557 | E2: 1656 | F2: 1/331901-333557tu | G2: 1/299910-300620cv | I2: 1 | J2: {=INDEX('Sub Trecho'!$F$2:$F$53,MATCH(1,IF('Sub Trecho'!$C$2:$C$53=A2,IF('Sub Trecho'!$H$2:$H$53<=B2,IF('Sub Trecho'!$I$2:$I$53>=B2,0)))))} -> LAP-LMG | K2: {=INDEX('Sub Trecho'!$D$2:$D$53,MATCH(1,IF('Sub Trecho'!$C$2:$C$53=A2,IF('Sub Trecho'!$H$2:$H$53<=B2,IF('Sub Trecho'!$I$2:$I$53>=B2,0)))))} -> 1
A3: 1 | B3: 334.935 | C3: 334.627 | D3: 335.242 | E3: 615 | F3: 1/334627-335242tu | G3: 1/299910-300620cv | I3: 2 | J3: {=INDEX('Sub Trecho'!$F$2:$F$53,MATCH(1,IF('Sub Trecho'!$C$2:$C$53=A3,IF('Sub Trecho'!$H$2:$H$53<=B3,IF('Sub Trecho'!$I$2:$I$53>=B3,0)))))} -> LAP-LMG | K3: {=INDEX('Sub Trecho'!$D$2:$D$53,MATCH(1,IF('Sub Trecho'!$C$2:$C$53=A3,IF('Sub Trecho'!$H$2:$H$53<=B3,IF('Sub Trecho'!$I$2:$I$53>=B3,0)))))} -> 1
A4: 6 | B4: 343.77 | C4: 343.588 | D4: 343.951 | E4: 363 | F4: 6/343588-343951tu | G4: 6/343430-344520tg | I4: 3 | J4: {=INDEX('Sub Trecho'!$F$2:$F$53,MATCH(1,IF('Sub Trecho'!$C$2:$C$53=A4,IF('Sub Trecho'!$H$2:$H$53<=B4,IF('Sub Trecho'!$I$2:$I$53>=B4,0)))))} -> LLZ-LUS | K4: {=INDEX('Sub Trecho'!$D$2:$D$53,MATCH(1,IF('Sub Trecho'!$C$2:$C$53=A4,IF('Sub Trecho'!$H$2:$H$53<=B4,IF('Sub Trecho'!$I$2:$I$53>=B4,0)))))} -> 6
A5: 7 | B5: 416.072 | C5: 415.929 | D5: 416.214 | E5: 285 | F5: 7/415929-416214tu | G5: 7/415650-416160cv | I5: 4 | J5: {=INDEX('Sub Trecho'!$F$2:$F$53,MATCH(1,IF('Sub Trecho'!$C$2:$C$53=A5,IF('Sub Trecho'!$H$2:$H$53<=B5,IF('Sub Trecho'!$I$2:$I$53>=B5,0)))))} -> LIH-LFI | K5: {=INDEX('Sub Trecho'!$D$2:$D$53,MATCH(1,IF('Sub Trecho'!$C$2:$C$53=A5,IF('Sub Trecho'!$H$2:$H$53<=B5,IF('Sub Trecho'!$I$2:$I$53>=B5,0)))))} -> 7
A6: 7 | B6: 425.103 | C6: 425.046 | D6: 425.159 | E6: 113 | F6: 7/425046-425159tu | G6: 7/424737-425087cv | I6: 5 | J6: {=INDEX('Sub Trecho'!$F$2:$F$53,MATCH(1,IF('Sub Trecho'!$C$2:$C$53=A6,IF('Sub Trecho'!$H$2:$H$53<=B6,IF('Sub Trecho'!$I$2:$I$53>=B6,0)))))} -> LFI-LOD | K6: {=INDEX('Sub Trecho'!$D$2:$D$53,MATCH(1,IF('Sub Trecho'!$C$2:$C$53=A6,IF('Sub Trecho'!$H$2:$H$53<=B6,IF('Sub Trecho'!$I$2:$I$53>=B6,0)))))} -> 7
A7: 7 | B7: 425.645 | C7: 425.579 | D7: 425.711 | E7: 132 | F7: 7/425579-425711tu | G7: 7/425224-425724cv | I7: 6 | J7: {=INDEX('Sub Trecho'!$F$2:$F$53,MATCH(1,IF('Sub Trecho'!$C$2:$C$53=A7,IF('Sub Trecho'!$H$2:$H$53<=B7,IF('Sub Trecho'!$I$2:$I$53>=B7,0)))))} -> LFI-LOD | K7: {=INDEX('Sub Trecho'!$D$2:$D$53,MATCH(1,IF('Sub Trecho'!$C$2:$C$53=A7,IF('Sub Trecho'!$H$2:$H$53<=B7,IF('Sub Trecho'!$I$2:$I$53>=B7,0)))))} -> 7
A8: 7 | B8: 426.359 | C8: 426.215 | D8: 426.503 | E8: 288 | F8: 7/426215-426503tu | G8: 7/425833-426293cv | I8: 7 | J8: {=INDEX('Sub Trecho'!$F$2:$F$53,MATCH(1,IF('Sub Trecho'!$C$2:$C$53=A8,IF('Sub Trecho'!$H$2:$H$53<=B8,IF('Sub Trecho'!$I$2:$I$53>=B8,0)))))} -> LFI-LOD | K8: {=INDEX('Sub Trecho'!$D$2:$D$53,MATCH(1,IF('Sub Trecho'!$C$2:$C$53=A8,IF('Sub Trecho'!$H$2:$H$53<=B8,IF('Sub Trecho'!$I$2:$I$53>=B8,0)))))} -> 7
A9: 7 | B9: 427.575 | C9: 427.274 | D9: 427.876 | E9: 602 | F9: 7/427274-427876tu | G9: 7/427236-427546cv | I9: 8 | J9: {=INDEX('Sub Trecho'!$F$2:$F$53,MATCH(1,IF('Sub Trecho'!$C$2:$C$53=A9,IF('Sub Trecho'!$H$2:$H$53<=B9,IF('Sub Trecho'!$I$2:$I$53>=B9,0)))))} -> LFI-LOD | K9: {=INDEX('Sub Trecho'!$D$2:$D$53,MATCH(1,IF('Sub Trecho'!$C$2:$C$53=A9,IF('Sub Trecho'!$H$2:$H$53<=B9,IF('Sub Trecho'!$I$2:$I$53>=B9,0)))))} -> 7
A10: 7 | B10: 439.417 | C10: 439.316 | D10: 439.518 | E10: 202 | F10: 7/439316-439518tu | G10: 7/439250-439620cv | I10: 9 | J10: {=INDEX('Sub Trecho'!$F$2:$F$53,MATCH(1,IF('Sub Trecho'!$C$2:$C$53=A10,IF('Sub Trecho'!$H$2:$H$53<=B10,IF('Sub Trecho'!$I$2:$I$53>=B10,0)))))} -> LFI-LOD | K10: {=INDEX('Sub Trecho'!$D$2:$D$53,MATCH(1,IF('Sub Trecho'!$C$2:$C$53=A10,IF('Sub Trecho'!$H$2:$H$53<=B10,IF('Sub Trecho'!$I$2:$I$53>=B10,0)))))} -> 7
A11: 7 | B11: 480.04 | C11: 479.906 | D11: 480.173 | E11: 267 | F11: 7/479906-480173tu | G11: 7/479588-480015tg | I11: 10 | J11: {=INDEX('Sub Trecho'!$F$2:$F$53,MATCH(1,IF('Sub Trecho'!$C$2:$C$53=A11,IF('Sub Trecho'!$H$2:$H$53<=B11,IF('Sub Trecho'!$I$2:$I$53>=B11,0)))))} -> LFI-LOD | K11: {=INDEX('Sub Trecho'!$D$2:$D$53,MATCH(1,IF('Sub Trecho'!$C$2:$C$53=A11,IF('Sub Trecho'!$H$2:$H$53<=B11,IF('Sub Trecho'!$I$2:$I$53>=B11,0)))))} -> 7
A12: 7 | B12: 480.584 | C12: 480.441 | D12: 480.726 | E12: 285 | F12: 7/480441-480726tu | G12: 7/480315-480671tg | I12: 11 | J12: {=INDEX('Sub Trecho'!$F$2:$F$53,MATCH(1,IF('Sub Trecho'!$C$2:$C$53=A12,IF('Sub Trecho'!$H$2:$H$53<=B12,IF('Sub Trecho'!$I$2:$I$53>=B12,0)))))} -> LFI-LOD | K12: {=INDEX('Sub Trecho'!$D$2:$D$53,MATCH(1,IF('Sub Trecho'!$C$2:$C$53=A12,IF('Sub Trecho'!$H$2:$H$53<=B12,IF('Sub Trecho'!$I$2:$I$53>=B12,0)))))} -> 7
A13: 7 | B13: 484.546 | C13: 484.321 | D13: 484.771 | E13: 450 | F13: 7/484321-484771tu | G13: 7/483740-484860cv | I13: 12 | J13: {=INDEX('Sub Trecho'!$F$2:$F$53,MATCH(1,IF('Sub Trecho'!$C$2:$C$53=A13,IF('Sub Trecho'!$H$2:$H$53<=B13,IF('Sub Trecho'!$I$2:$I$53>=B13,0)))))} -> LFI-LOD | K13: {=INDEX('Sub Trecho'!$D$2:$D$53,MATCH(1,IF('Sub Trecho'!$C$2:$C$53=A13,IF('Sub Trecho'!$H$2:$H$53<=B13,IF('Sub Trecho'!$I$2:$I$53>=B13,0)))))} -> 7
... A41: 14 | B41: 125.824 | C41: 125.799 | D41: 125.848 | E41: 49 | F41: 14/125799-125848tu | G41: 14/125722-125840cv | I41: 40 | J41: {=INDEX('Sub Trecho'!$F$2:$F$53,MATCH(1,IF('Sub Trecho'!$C$2:$C$53=A41,IF('Sub Trecho'!$H$2:$H$53<=B41,IF('Sub Trecho'!$I$2:$I$53>=B41,0)))))} -> LSB-LJG | K41: {=INDEX('Sub Trecho'!$D$2:$D$53,MATCH(1,IF('Sub Trecho'!$C$2:$C$53=A41,IF('Sub Trecho'!$H$2:$H$53<=B41,IF('Sub Trecho'!$I$2:$I$53>=B41,0)))))} -> 14
A42: 15 | B42: 5.915 | C42: 5.8 | D42: 6.03 | E42: 230 | F42: 15/005800-006030tu | I42: 41 | J42: {=INDEX('Sub Trecho'!$F$2:$F$53,MATCH(1,IF('Sub Trecho'!$C$2:$C$53=A42,IF('Sub Trecho'!$H$2:$H$53<=B42,IF('Sub Trecho'!$I$2:$I$53>=B42,0)))))} -> LUN-LNG | K42: {=INDEX('Sub Trecho'!$D$2:$D$53,MATCH(1,IF('Sub Trecho'!$C$2:$C$53=A42,IF('Sub Trecho'!$H$2:$H$53<=B42,IF('Sub Trecho'!$I$2:$I$53>=B42,0)))))} -> 15
A43: 15 | B43: 8.285 | C43: 8.15 | D43: 8.42 | E43: 270 | F43: 15/008150-008420tu | I43: 42 | J43: {=INDEX('Sub Trecho'!$F$2:$F$53,MATCH(1,IF('Sub Trecho'!$C$2:$C$53=A43,IF('Sub Trecho'!$H$2:$H$53<=B43,IF('Sub Trecho'!$I$2:$I$53>=B43,0)))))} -> LUN-LNG | K43: {=INDEX('Sub Trecho'!$D$2:$D$53,MATCH(1,IF('Sub Trecho'!$C$2:$C$53=A43,IF('Sub Trecho'!$H$2:$H$53<=B43,IF('Sub Trecho'!$I$2:$I$53>=B43,0)))))} -> 15
A44: 16 | B44: 38.438 | C44: 38.284 | D44: 38.591 | E44: 307 | F44: 16/038284-038591tu | G44: 16/038021-038461tg | I44: 43 | J44: {=INDEX('Sub Trecho'!$F$2:$F$53,MATCH(1,IF('Sub Trecho'!$C$2:$C$53=A44,IF('Sub Trecho'!$H$2:$H$53<=B44,IF('Sub Trecho'!$I$2:$I$53>=B44,0)))))} -> LRI-LIA | K44: {=INDEX('Sub Trecho'!$D$2:$D$53,MATCH(1,IF('Sub Trecho'!$C$2:$C$53=A44,IF('Sub Trecho'!$H$2:$H$53<=B44,IF('Sub Trecho'!$I$2:$I$53>=B44,0)))))} -> 16
A45: 16 | B45: 113.76 | C45: 113.641 | D45: 113.879 | E45: 238 | F45: 16/113641-113879tu | G45: 16/113462-114041tg | I45: 44 | J45: {=INDEX('Sub Trecho'!$F$2:$F$53,MATCH(1,IF('Sub Trecho'!$C$2:$C$53=A45,IF('Sub Trecho'!$H$2:$H$53<=B45,IF('Sub Trecho'!$I$2:$I$53>=B45,0)))))} -> LIA-LFJ | K45: {=INDEX('Sub Trecho'!$D$2:$D$53,MATCH(1,IF('Sub Trecho'!$C$2:$C$53=A45,IF('Sub Trecho'!$H$2:$H$53<=B45,IF('Sub Trecho'!$I$2:$I$53>=B45,0)))))} -> 16
A46: 16 | B46: 114.231 | C46: 114.134 | D46: 114.327 | E46: 193 | F46: 16/114134-114327tu | G46: 16/114041-114314cv | I46: 45 | J46: {=INDEX('Sub Trecho'!$F$2:$F$53,MATCH(1,IF('Sub Trecho'!$C$2:$C$53=A46,IF('Sub Trecho'!$H$2:$H$53<=B46,IF('Sub Trecho'!$I$2:$I$53>=B46,0)))))} -> LIA-LFJ | K46: {=INDEX('Sub Trecho'!$D$2:$D$53,MATCH(1,IF('Sub Trecho'!$C$2:$C$53=A46,IF('Sub Trecho'!$H$2:$H$53<=B46,IF('Sub Trecho'!$I$2:$I$53>=B46,0)))))} -> 16
A47: 16 | B47: 115.289 | C47: 115.169 | D47: 115.408 | E47: 239 | F47: 16/115169-115408tu | G47: 16/114992-115202tg | I47: 46 | J47: {=INDEX('Sub Trecho'!$F$2:$F$53,MATCH(1,IF('Sub Trecho'!$C$2:$C$53=A47,IF('Sub Trecho'!$H$2:$H$53<=B47,IF('Sub Trecho'!$I$2:$I$53>=B47,0)))))} -> LIA-LFJ | K47: {=INDEX('Sub Trecho'!$D$2:$D$53,MATCH(1,IF('Sub Trecho'!$C$2:$C$53=A47,IF('Sub Trecho'!$H$2:$H$53<=B47,IF('Sub Trecho'!$I$2:$I$53>=B47,0)))))} -> 16
A48: 16 | B48: 115.805 | C48: 115.703 | D48: 115.906 | E48: 203 | F48: 16/115703-115906tu | G48: 16/115436-115723cv | I48: 47 | J48: {=INDEX('Sub Trecho'!$F$2:$F$53,MATCH(1,IF('Sub Trecho'!$C$2:$C$53=A48,IF('Sub Trecho'!$H$2:$H$53<=B48,IF('Sub Trecho'!$I$2:$I$53>=B48,0)))))} -> LIA-LFJ | K48: {=INDEX('Sub Trecho'!$D$2:$D$53,MATCH(1,IF('Sub Trecho'!$C$2:$C$53=A48,IF('Sub Trecho'!$H$2:$H$53<=B48,IF('Sub Trecho'!$I$2:$I$53>=B48,0)))))} -> 16
A49: 16 | B49: 116.161 | C49: 116.028 | D49: 116.293 | E49: 265 | F49: 16/116028-116293tu | G49: 16/115807-116334cv | I49: 48 | J49: {=INDEX('Sub Trecho'!$F$2:$F$53,MATCH(1,IF('Sub Trecho'!$C$2:$C$53=A49,IF('Sub Trecho'!$H$2:$H$53<=B49,IF('Sub Trecho'!$I$2:$I$53>=B49,0)))))} -> LIA-LFJ | K49: {=INDEX('Sub Trecho'!$D$2:$D$53,MATCH(1,IF('Sub Trecho'!$C$2:$C$53=A49,IF('Sub Trecho'!$H$2:$H$53<=B49,IF('Sub Trecho'!$I$2:$I$53>=B49,0)))))} -> 16
A50: 16 | B50: 116.398 | C50: 116.338 | D50: 116.458 | E50: 120 | F50: 16/116338-116458tu | G50: 16/116334-116452tg | I50: 49 | J50: {=INDEX('Sub Trecho'!$F$2:$F$53,MATCH(1,IF('Sub Trecho'!$C$2:$C$53=A50,IF('Sub Trecho'!$H$2:$H$53<=B50,IF('Sub Trecho'!$I$2:$I$53>=B50,0)))))} -> LIA-LFJ | K50: {=INDEX('Sub Trecho'!$D$2:$D$53,MATCH(1,IF('Sub Trecho'!$C$2:$C$53=A50,IF('Sub Trecho'!$H$2:$H$53<=B50,IF('Sub Trecho'!$I$2:$I$53>=B50,0)))))} -> 16
A51: 16 | B51: 116.828 | C51: 116.638 | D51: 117.018 | E51: 380 | F51: 16/116638-117018tu | G51: 16/116452-116860cv | I51: 50 | J51: {=INDEX('Sub Trecho'!$F$2:$F$53,MATCH(1,IF('Sub Trecho'!$C$2:$C$53=A51,IF('Sub Trecho'!$H$2:$H$53<=B51,IF('Sub Trecho'!$I$2:$I$53>=B51,0)))))} -> LIA-LFJ | K51: {=INDEX('Sub Trecho'!$D$2:$D$53,MATCH(1,IF('Sub Trecho'!$C$2:$C$53=A51,IF('Sub Trecho'!$H$2:$H$53<=B51,IF('Sub Trecho'!$I$2:$I$53>=B51,0)))))} -> 16
A52: 16 | B52: 118.159 | C52: 118.081 | D52: 118.236 | E52: 155 | F52: 16/118081-118236tu | G52: 16/118017-118100tg | I52: 51 | J52: {=INDEX('Sub Trecho'!$F$2:$F$53,MATCH(1,IF('Sub Trecho'!$C$2:$C$53=A52,IF('Sub Trecho'!$H$2:$H$53<=B52,IF('Sub Trecho'!$I$2:$I$53>=B52,0)))))} -> LIA-LFJ | K52: {=INDEX('Sub Trecho'!$D$2:$D$53,MATCH(1,IF('Sub Trecho'!$C$2:$C$53=A52,IF('Sub Trecho'!$H$2:$H$53<=B52,IF('Sub Trecho'!$I$2:$I$53>=B52,0)))))} -> 16
A53: 16 | B53: 120.1 | C53: 120.017 | D53: 120.183 | E53: 166 | F53: 16/120017-120183tu | G53: 16/119968-120345cv | I53: 52 | J53: {=INDEX('Sub Trecho'!$F$2:$F$53,MATCH(1,IF('Sub Trecho'!$C$2:$C$53=A53,IF('Sub Trecho'!$H$2:$H$53<=B53,IF('Sub Trecho'!$I$2:$I$53>=B53,0)))))} -> LIA-LFJ | K53: {=INDEX('Sub Trecho'!$D$2:$D$53,MATCH(1,IF('Sub Trecho'!$C$2:$C$53=A53,IF('Sub Trecho'!$H$2:$H$53<=B53,IF('Sub Trecho'!$I$2:$I$53>=B53,0)))))} -> 16
A54: 16 | B54: 121.597 | C54: 120.828 | D54: 122.365 | E54: 1537 | F54: 16/120828-122365tu | G54: 16/120750-122002tg | I54: 53 | J54: {=INDEX('Sub Trecho'!$F$2:$F$53,MATCH(1,IF('Sub Trecho'!$C$2:$C$53=A54,IF('Sub Trecho'!$H$2:$H$53<=B54,IF('Sub Trecho'!$I$2:$I$53>=B54,0)))))} -> LIA-LFJ | K54: {=INDEX('Sub Trecho'!$D$2:$D$53,MATCH(1,IF('Sub Trecho'!$C$2:$C$53=A54,IF('Sub Trecho'!$H$2:$H$53<=B54,IF('Sub Trecho'!$I$2:$I$53>=B54,0)))))} -> 16
A55: 16 | B55: 124.47 | C55: 124.199 | D55: 124.741 | E55: 542 | F55: 16/124199-124741tu | G55: 16/123497-124221cv | I55: 54 | J55: {=INDEX('Sub Trecho'!$F$2:$F$53,MATCH(1,IF('Sub Trecho'!$C$2:$C$53=A55,IF('Sub Trecho'!$H$2:$H$53<=B55,IF('Sub Trecho'!$I$2:$I$53>=B55,0)))))} -> LIA-LFJ | K55: {=INDEX('Sub Trecho'!$D$2:$D$53,MATCH(1,IF('Sub Trecho'!$C$2:$C$53=A55,IF('Sub Trecho'!$H$2:$H$53<=B55,IF('Sub Trecho'!$I$2:$I$53>=B55,0)))))} -> 16
... A141: 19 | B141: 55.43 | C141: 55.14 | D141: 55.72 | E141: 580 | F141: 19/055140-055720tu | G141: 19/054971-056120cv | I141: 140 | J141: {=INDEX('Sub Trecho'!$F$2:$F$53,MATCH(1,IF('Sub Trecho'!$C$2:$C$53=A141,IF('Sub Trecho'!$H$2:$H$53<=B141,IF('Sub Trecho'!$I$2:$I$53>=B141,0)))))} -> NRO-NPF | K141: {=INDEX('Sub Trecho'!$D$2:$D$53,MATCH(1,IF('Sub Trecho'!$C$2:$C$53=A141,IF('Sub Trecho'!$H$2:$H$53<=B141,IF('Sub Trecho'!$I$2:$I$53>=B141,0)))))} -> 19
A142: 19 | B142: 69.409 | C142: 69.258 | D142: 69.559 | E142: 301 | F142: 19/069258-069559tu | G142: 19/069105-069450tg | H142: TÚNEL 8 | I142: 141 | J142: {=INDEX('Sub Trecho'!$F$2:$F$53,MATCH(1,IF('Sub Trecho'!$C$2:$C$53=A142,IF('Sub Trecho'!$H$2:$H$53<=B142,IF('Sub Trecho'!$I$2:$I$53>=B142,0)))))} -> NRO-NPF | K142: {=INDEX('Sub Trecho'!$D$2:$D$53,MATCH(1,IF('Sub Trecho'!$C$2:$C$53=A142,IF('Sub Trecho'!$H$2:$H$53<=B142,IF('Sub Trecho'!$I$2:$I$53>=B142,0)))))} -> 19
A143: 19 | B143: 70.522 | C143: 70.255 | D143: 70.789 | E143: 534 | F143: 19/070255-070789tu | G143: 19/069655-070450tg | H143: TÚNEL 7 | I143: 142 | J143: {=INDEX('Sub Trecho'!$F$2:$F$53,MATCH(1,IF('Sub Trecho'!$C$2:$C$53=A143,IF('Sub Trecho'!$H$2:$H$53<=B143,IF('Sub Trecho'!$I$2:$I$53>=B143,0)))))} -> NRO-NPF | K143: {=INDEX('Sub Trecho'!$D$2:$D$53,MATCH(1,IF('Sub Trecho'!$C$2:$C$53=A143,IF('Sub Trecho'!$H$2:$H$53<=B143,IF('Sub Trecho'!$I$2:$I$53>=B143,0)))))} -> 19
A144: 19 | B144: 72.203 | C144: 72.073 | D144: 72.333 | E144: 260 | F144: 19/072073-072333tu | G144: 19/071795-072780cv | I144: 143 | J144: {=INDEX('Sub Trecho'!$F$2:$F$53,MATCH(1,IF('Sub Trecho'!$C$2:$C$53=A144,IF('Sub Trecho'!$H$2:$H$53<=B144,IF('Sub Trecho'!$I$2:$I$53>=B144,0)))))} -> NRO-NPF | K144: {=INDEX('Sub Trecho'!$D$2:$D$53,MATCH(1,IF('Sub Trecho'!$C$2:$C$53=A144,IF('Sub Trecho'!$H$2:$H$53<=B144,IF('Sub Trecho'!$I$2:$I$53>=B144,0)))))} -> 19
A145: 19 | B145: 74.748 | C145: 74.52 | D145: 74.976 | E145: 456 | F145: 19/074520-074976tu | G145: 19/074012-074538cv | I145: 144 | J145: {=INDEX('Sub Trecho'!$F$2:$F$53,MATCH(1,IF('Sub Trecho'!$C$2:$C$53=A145,IF('Sub Trecho'!$H$2:$H$53<=B145,IF('Sub Trecho'!$I$2:$I$53>=B145,0)))))} -> NRO-NPF | K145: {=INDEX('Sub Trecho'!$D$2:$D$53,MATCH(1,IF('Sub Trecho'!$C$2:$C$53=A145,IF('Sub Trecho'!$H$2:$H$53<=B145,IF('Sub Trecho'!$I$2:$I$53>=B145,0)))))} -> 19
A146: 19 | B146: 76.008 | C146: 75.867 | D146: 76.149 | E146: 282 | F146: 19/075867-076149tu | G146: 19/075682-075872cv | I146: 145 | J146: {=INDEX('Sub Trecho'!$F$2:$F$53,MATCH(1,IF('Sub Trecho'!$C$2:$C$53=A146,IF('Sub Trecho'!$H$2:$H$53<=B146,IF('Sub Trecho'!$I$2:$I$53>=B146,0)))))} -> NRO-NPF | K146: {=INDEX('Sub Trecho'!$D$2:$D$53,MATCH(1,IF('Sub Trecho'!$C$2:$C$53=A146,IF('Sub Trecho'!$H$2:$H$53<=B146,IF('Sub Trecho'!$I$2:$I$53>=B146,0)))))} -> 19
A147: 19 | B147: 78.261 | C147: 78.046 | D147: 78.475 | E147: 429 | F147: 19/078046-078475tu | G147: 19/077976-078205cv | I147: 146 | J147: {=INDEX('Sub Trecho'!$F$2:$F$53,MATCH(1,IF('Sub Trecho'!$C$2:$C$53=A147,IF('Sub Trecho'!$H$2:$H$53<=B147,IF('Sub Trecho'!$I$2:$I$53>=B147,0)))))} -> NRO-NPF | K147: {=INDEX('Sub Trecho'!$D$2:$D$53,MATCH(1,IF('Sub Trecho'!$C$2:$C$53=A147,IF('Sub Trecho'!$H$2:$H$53<=B147,IF('Sub Trecho'!$I$2:$I$53>=B147,0)))))} -> 19
A148: 19 | B148: 83.211 | C148: 83.073 | D148: 83.349 | E148: 276 | F148: 19/083073-083349tu | G148: 19/082080-083086tg | I148: 147 | J148: {=INDEX('Sub Trecho'!$F$2:$F$53,MATCH(1,IF('Sub Trecho'!$C$2:$C$53=A148,IF('Sub Trecho'!$H$2:$H$53<=B148,IF('Sub Trecho'!$I$2:$I$53>=B148,0)))))} -> NRO-NPF | K148: {=INDEX('Sub Trecho'!$D$2:$D$53,MATCH(1,IF('Sub Trecho'!$C$2:$C$53=A148,IF('Sub Trecho'!$H$2:$H$53<=B148,IF('Sub Trecho'!$I$2:$I$53>=B148,0)))))} -> 19
A149: 19 | B149: 95.184 | C149: 95.041 | D149: 95.327 | E149: 286 | F149: 19/095041-095327tu | G149: 19/094997-095307tg | I149: 148 | J149: {=INDEX('Sub Trecho'!$F$2:$F$53,MATCH(1,IF('Sub Trecho'!$C$2:$C$53=A149,IF('Sub Trecho'!$H$2:$H$53<=B149,IF('Sub Trecho'!$I$2:$I$53>=B149,0)))))} -> NRO-NPF | K149: {=INDEX('Sub Trecho'!$D$2:$D$53,MATCH(1,IF('Sub Trecho'!$C$2:$C$53=A149,IF('Sub Trecho'!$H$2:$H$53<=B149,IF('Sub Trecho'!$I$2:$I$53>=B149,0)))))} -> 19
A150: 21 | B150: 55.676 | C150: 55.399 | D150: 55.953 | E150: 554 | F150: 21/055399-055953tu | G150: 2/200360-201360tg | I150: 149 | J150: {=INDEX('Sub Trecho'!$F$2:$F$53,MATCH(1,IF('Sub Trecho'!$C$2:$C$53=A150,IF('Sub Trecho'!$H$2:$H$53<=B150,IF('Sub Trecho'!$I$2:$I$53>=B150,0)))))} -> NRO-NGL | K150: {=INDEX('Sub Trecho'!$D$2:$D$53,MATCH(1,IF('Sub Trecho'!$C$2:$C$53=A150,IF('Sub Trecho'!$H$2:$H$53<=B150,IF('Sub Trecho'!$I$2:$I$53>=B150,0)))))} -> 21
A151: 21 | B151: 83.63 | C151: 83.515 | D151: 83.745 | E151: 230 | F151: 21/083515-083745tu | G151: 2/200360-201360tg | I151: 150 | J151: {=INDEX('Sub Trecho'!$F$2:$F$53,MATCH(1,IF('Sub Trecho'!$C$2:$C$53=A151,IF('Sub Trecho'!$H$2:$H$53<=B151,IF('Sub Trecho'!$I$2:$I$53>=B151,0)))))} -> NRO-NGL | K151: {=INDEX('Sub Trecho'!$D$2:$D$53,MATCH(1,IF('Sub Trecho'!$C$2:$C$53=A151,IF('Sub Trecho'!$H$2:$H$53<=B151,IF('Sub Trecho'!$I$2:$I$53>=B151,0)))))} -> 21
A152: 21 | B152: 97.491 | C152: 97.301 | D152: 97.682 | E152: 381 | F152: 21/097300-097682tu | G152: 2/200360-201360tg | I152: 151 | J152: {=INDEX('Sub Trecho'!$F$2:$F$53,MATCH(1,IF('Sub Trecho'!$C$2:$C$53=A152,IF('Sub Trecho'!$H$2:$H$53<=B152,IF('Sub Trecho'!$I$2:$I$53>=B152,0)))))} -> NRO-NGL | K152: {=INDEX('Sub Trecho'!$D$2:$D$53,MATCH(1,IF('Sub Trecho'!$C$2:$C$53=A152,IF('Sub Trecho'!$H$2:$H$53<=B152,IF('Sub Trecho'!$I$2:$I$53>=B152,0)))))} -> 21
...

Sheet Sub Trecho
A1: Malha | B1: Trecho | C1: N_Sub | D1: Sub_Dupli | E1: Sub_Trecho | F1: Sub_Trecho2 | G1: Km_Sub_Trecho2 | H1: Km_Inicio | I1: Km_Fim | J1: Estado | K1: Gerência | L1: PDT | M1: ID_PowerApps
A2: Métrica | B2: CN | C2: 1 | D2: 1 | E2: LLD-LMG | F2: LLD-LAP | G2: 217-268 | H2: 217 | I2: 268 | J2: PR | K2: Central Norte | M2: 1
A3: Métrica | B3: CN | C3: 1 | D3: 1 | E3: LLD-LMG | F3: LAP-LMG | G3: 268-340 | H3: 268 | I3: 431 | J3: PR | K3: Central Norte | M3: 2
A4: Métrica | B4: CN | C4: 2 | D4: 2 | E4: LMQ-LLD | F4: LMQ-LLJ | G4: 0-103 | H4: 0 | I4: 103 | J4: PR | K4: Central Norte | M4: 3
A5: Métrica | B5: CN | C5: 2 | D5: 2 | E5: LMQ-LLD | F5: LLJ-LLD | G5: 103-217 | H5: 103 | I5: 217 | J5: PR | K5: Central Norte | M5: 4
A6: Métrica | B6: CN | C6: 3 | D6: 3 | E6: LMQ-LMU | F6: LMQ-LMU | G6: 27-210 | H6: 0 | I6: 210 | J6: PR | K6: Central Norte | M6: 5
A7: Métrica | B7: CN | C7: 4 | D7: 4 | E7: LUS-LMU | F7: LUS-LMU | G7: 104-222 | H7: 75 | I7: 226 | J7: PR | K7: Central Norte | M7: 6
A8: Métrica | B8: CN | C8: 5 | D8: 5 | E8: LMU-LHA | F8: LMU-LHA | G8: 0-120 | H8: 0 | I8: 120 | J8: PR | K8: Central Norte | M8: 7
A9: Métrica | B9: CN | C9: 6 | D9: 6 | E9: LLZ-LUS | F9: LLZ-LUS | G9: 378-249 | H9: 249 | I9: 379 | J9: PR | K9: Central Norte | M9: 8
A10: Métrica | B10: CN | C10: 7 | D10: 7 | E10: LUS-LAP | F10: LUS-LIH | G10: 248 - 334 | H10: 248 | I10: 334 | J10: PR | K10: Central Norte | M10: 9
A11: Métrica | B11: CN | C11: 7 | D11: 7 | E11: LUS-LAP | F11: LIH-LFI | G11: 334 - 420 | H11: 334 | I11: 420 | J11: PR | K11: Central Norte | M11: 10
A12: Métrica | B12: CN | C12: 7 | D12: 7 | E12: LUS-LAP | F12: LFI-LOD | G12: 420 - 500 | H12: 420 | I12: 500 | J12: PR | K12: Central Norte | M12: 11
A13: Métrica | B13: CN | C13: 7 | D13: 7 | E13: LUS-LAP | F13: LOD-LAP | G13: 500 - 583 | H13: 500 | I13: 583 | J13: PR | K13: Central Norte | M13: 12
... A53: Métrica | B53: CS | C53: LAT | D53: LAT | E53: LMR-LAT | F53: LMR-LAT | G53: 0-14 | H53: 0 | I53: 16 | J53: PR | K53: Central Serrras | M53: 101
